Workbook
Name ListaFluxo: PARAMETROS!$M$6:$M$51
Name ListaGerentes: PARAMETROS!$D$6:$D$56
Name ListaIndicadores: PARAMETROS!$S$6:$S$51
Name ListaMandato: PARAMETROS!$P$6:$P$49
Name ListaMotivos: PARAMETROS!$V$6:$V$51
Name ListaOperacoes: PARAMETROS!$G$6:$G$57
Name ListaParceiros: PARAMETROS!$A$6:$A$111
Name ListaStatus: PARAMETROS!$J$6:$J$52

Sheet João Pullig
A6: CLIENTE | B6: OPERAÇÃO | C6: VALOR | D6: FEE | E6: RECEITA | F6: MANDATO | G6: QTD | H6: INSTITUIÇÃO | I6: PARCEIRO INDICADOR | J6: ATUALIZAÇÃO | K6: FLUXO | L6: STATUS | M6: DATA FECHAMENTO | N6: MOTIVO DE RECUSA | O6: OBSERVAÇÃO
A7: CGPM CONSTRUTORA GOIANIA | B7: ⁠Antecipação de Recebíveis | C7: 3000000 | D7: 0.02 | E7: =D7*C7 -> 60000 | F7: Assinado | G7: 1 | H7: 7 ALDABRAN | I7: PJC Consultoria | J7: 46288 | K7: Em andamento | L7: Análise de Crédito | O7: Contratos públicos
A8: CGPM CONSTRUTORA GOIANIA | B8: ⁠Antecipação de Recebíveis | C8: 4000000 | D8: 0.02 | E8: =D8*C8 -> 80000 | F8: Assinado | G8: 1 | H8: DIAMOND | I8: PJC Consultoria | J8: 46288 | K8: Em andamento | L8: Análise de Crédito | O8: Contratos públicos
A9: PEDRO BRIDI | B9: ⁠Credito Rural | C9: 8000000 | D9: 0.01 | E9: =D9*C9 -> 80000 | F9: Não enviado | G9: 1 | H9: 7 ALDABRAN | I9: ⁠VM Consultoria | J9: 46288 | K9: Em andamento | L9: Análise de Crédito
A10: GRUPO GR ALIMENTOS | B10: Capital de Giro | C10: 40000000 | D10: 0.01 | E10: =D10*C10 -> 400000 | F10: Não enviado | G10: 1 | H10: SAPIENS CAPITAL | I10: ⁠MB Finance | J10: 46288 | K10: Em andamento | L10: Cadastro
A11: GRUPO GR ALIMENTOS | B11: ⁠Antecipação de Recebíveis | C11: 2000000 | D11: 0.01 | E11: =D11*C11 -> 20000 | F11: Não enviado | G11: 1 | H11: SAPIENS CAPITAL | I11: ⁠MB Finance | J11: 46288 | K11: Em andamento | L11: Cadastro
A12: GRUPO GR ALIMENTOS | B12: Capital de Giro | C12: 40000000 | D12: 0.01 | E12: =D12*C12 -> 400000 | F12: Não enviado | G12: 1 | H12: INVISTA FIDC | I12: ⁠MB Finance | J12: 46288 | K12: Em andamento | L12: Cadastro
A13: ROV ENGENHARIA E CONSTRUCAO LTDA | B13: ⁠Antecipação de Recebíveis | C13: 1000000 | D13: 0.04 | E13: =D13*C13 -> 40000 | F13: Não enviado | G13: 1 | H13: SAPIENS CAPITAL | I13: ⁠Blue Score | J13: 46288 | K13: Em andamento | L13: Aprovado
A14: ROV ENGENHARIA E CONSTRUCAO LTDA | B14: ⁠Antecipação de Recebíveis | C14: 1000000 | D14: 0.04 | E14: =D14*C14 -> 40000 | F14: Não enviado | G14: 1 | H14: OXIGENIO CAPITAL | I14: ⁠Blue Score | J14: 46288 | K14: Em andamento | L14: Análise de Crédito
A15: ROV ENGENHARIA E CONSTRUCAO LTDA | B15: ⁠Antecipação de Recebíveis | C15: 1000000 | D15: 0.04 | E15: =D15*C15 -> 40000 | F15: Não enviado | G15: 1 | H15: 7 ALDABRAN | I15: ⁠Blue Score | J15: 46288 | K15: Em andamento | L15: Análise de Crédito
A16: TISSOT MOVEIS LTDA | B16: Capital de Giro | C16: 3000000 | D16: 0.02 | E16: =D16*C16 -> 60000 | F16: Não enviado | G16: 1 | H16: NÃO ATRIBUÍDO | I16: PJC Consultoria | J16: 46288 | K16: Não enviado | L16: Cadastro
A17: SG FACAS ARTESANAIS | B17: ⁠Antecipação de Recebíveis | C17: 500000 | D17: 0.03 | E17: =D17*C17 -> 15000 | F17: Não enviado | G17: 1 | H17: NÃO ATRIBUÍDO | I17: PJC Consultoria | J17: 46288 | K17: Não enviado | L17: Cadastro
A18: LOBE CONTABILIDADE | B18: Pronampe | C18: 500000 | D18: 0.03 | E18: =D18*C18 -> 15000 | F18: Assinado | G18: 1 | H18: 7 ALDABRAN | I18: PJC Consultoria | J18: 46288 | K18: Em andamento | L18: Análise de Crédito
A19: RENOVADORA ALVORADA COMERCIO | B19: ⁠Antecipação de Recebíveis | C19: 300000 | D19: 0.03 | E19: =D19*C19 -> 9000 | F19: Não enviado | G19: 1 | H19: AFFIX FIDC | I19: PJC Consultoria | J19: 46288 | K19: Em andamento | L19: Análise de Crédito
A20: RENOVADORA ALVORADA COMERCIO | B20: ⁠Antecipação de Recebíveis | C20: 300000 | D20: 0.03 | E20: =D20*C20 -> 9000 | F20: Não enviado | G20: 1 | H20: DIAMOND | I20: PJC Consultoria | J20: 46288 | K20: Em andamento | L20: Análise de Crédito
... A37: ROTEC METAIS | B37: ⁠Antecipação de Recebíveis | C37: 500000 | D37: 0.02 | E37: =D37*C37 -> 10000 | F37: Não enviado | G37: 1 | H37: NÃO ATRIBUÍDO | I37: PJC Consultoria | J37: 46288 | K37: Não enviado | L37: Cadastro
E38: =D38*C38 -> 0
E39: =D39*C39 -> 0
E40: =D40*C40 -> 0
E41: =D41*C41 -> 0
E42: =D42*C42 -> 0
E43: =D43*C43 -> 0
E44: =D44*C44 -> 0
E45: =D45*C45 -> 0
E46: =D46*C46 -> 0
E47: =D47*C47 -> 0
E48: =D48*C48 -> 0
E49: =D49*C49 -> 0
... E277: =D277*C277 -> 0
E278: =IF(OR(C278="",D278=""),"",C278*D278)
E279: =IF(OR(C279="",D279=""),"",C279*D279)
E280: =IF(OR(C280="",D280=""),"",C280*D280)
E281: =IF(OR(C281="",D281=""),"",C281*D281)
E282: =IF(OR(C282="",D282=""),"",C282*D282)
E283: =IF(OR(C283="",D283=""),"",C283*D283)
E284: =IF(OR(C284="",D284=""),"",C284*D284)
E285: =IF(OR(C285="",D285=""),"",C285*D285)
E286: =IF(OR(C286="",D286=""),"",C286*D286)
E287: =IF(OR(C287="",D287=""),"",C287*D287)
E288: =IF(OR(C288="",D288=""),"",C288*D288)
...

Sheet Kaio Dias
A6: CLIENTE | B6: OPERAÇÃO | C6: VALOR | D6: FEE | E6: RECEITA | F6: MANDATO | G6: QTD | H6: INSTITUIÇÃO | I6: PARCEIRO INDICADOR | J6: ATUALIZAÇÃO | K6: FLUXO | L6: STATUS | M6: DATA FECHAMENTO | N6: MOTIVO DE RECUSA | O6: OBSERVAÇÃO
A7: SIMEMP SERVICOS TECNICOS E OBRAS LTDA | B7: Capital de Giro | C7: 700000 | D7: 0.015 | E7: =D7*C7 -> 10500 | F7: Enviado | G7: 1 | H7: SAPIENS CAPITAL | I7: PJC Consultoria | J7: 46287 | K7: Enviado | L7: Análise de Crédito | O7: Enviados contratos, aguardando retorno da analise
A8: SIMEMP SERVICOS TECNICOS E OBRAS LTDA | B8: Capital de Giro | C8: 5000000 | D8: 0.015 | E8: =D8*C8 -> 75000 | F8: Enviado | G8: 1 | H8: 7 ALDABRAN | I8: PJC Consultoria | J8: 46287 | K8: Enviado | L8: Análise de Crédito | O8: Enviados contratos recebidos, aguardando retorno
A9: SIMEMP SERVICOS TECNICOS E OBRAS LTDA | B9: ⁠Antecipação de Recebíveis | C9: 5000000 | D9: 0.015 | E9: =D9*C9 -> 75000 | F9: Enviado | G9: 1 | H9: DIAMOND | I9: PJC Consultoria | J9: 46287 | K9: Enviado | L9: Cadastro | O9: Cadastro enviado 22/09/2026
A10: MMA BRAZIL COMERCIO DE ALIMENTOS LTDA | B10: ⁠Antecipação de Recebíveis | C10: 300000 | D10: 0.03 | E10: =D10*C10 -> 9000 | F10: Assinado | G10: 1 | H10: SAPIENS CAPITAL | I10: PJC Consultoria | J10: 46287 | K10: Enviado | L10: Comitê | O10: Em comite de credito
A11: MMA BRAZIL COMERCIO DE ALIMENTOS LTDA | B11: Capital de Giro | C11: 300000 | D11: 0.03 | E11: =D11*C11 -> 9000 | F11: Assinado | G11: 1 | H11: 7 ALDABRAN | I11: PJC Consultoria | J11: 46287 | K11: Enviado | L11: Cadastro | O11: Aguardando documentação atualizada
A12: N DIDINI ENGENHARIA E CONSTRUCAO LTDA | B12: Capital de Giro | C12: 1500000 | D12: 0.03 | E12: =D12*C12 -> 45000 | F12: Assinado | G12: 1 | H12: 7 ALDABRAN | I12: PJC Consultoria | J12: 46287 | K12: Enviado | L12: Análise de Crédito | O12: Esta sendo feito trabalho para melhora do risco, aguardando retorno da cintia
A13: N DIDINI ENGENHARIA E CONSTRUCAO LTDA | B13: Capital de Giro | C13: 1500000 | D13: 0.03 | E13: =D13*C13 -> 45000 | F13: Assinado | G13: 1 | H13: DIAMOND | I13: PJC Consultoria | J13: 46288 | K13: Enviado | L13: Cadastro | O13: Subir documentação
A14: HIPERAGRO COMERCIO DE GRÃO LTDA | B14: ⁠Antecipação de Recebíveis | C14: 777242 | D14: 0.025 | E14: =D14*C14 -> 19431.05 | F14: Assinado | G14: 1 | H14: AFFIX FIDC | I14: PJC Consultoria | J14: 46287 | K14: Enviado | L14: Aprovado | O14: Op 1 - 1906,59 / Op 2 - 1794,50 / Op 3 - 2263 / Op 4 - 2.985,08 / Op 5 - 5000 Total a recebido R$ 13.949,17 / A receber R$ 5481,88
A15: INTEGRAL ALIMENTOS LTDA | B15: ⁠Antecipação de Recebíveis | C15: 1000000 | D15: 0.05 | E15: =D15*C15 -> 50000 | F15: Assinado | G15: 1 | H15: 7 ALDABRAN | I15: PJC Consultoria | J15: 46287 | K15: Enviado | L15: Comitê | O15: Feito reunião
A16: AGRICOLA RIZZI LTDA | B16: Capital de Giro | C16: 20000000 | D16: 0.01 | E16: =D16*C16 -> 200000 | F16: Assinado | G16: 1 | H16: 7 ALDABRAN | I16: PJC Consultoria | J16: 46288 | K16: Enviado | L16: Cadastro | O16: aguardando posição da documentação enviada
A17: AGRICOLA RIZZI LTDA | B17: ⁠Consórcio | C17: 4500000 | D17: 0.01 | E17: =D17*C17 -> 45000 | F17: Assinado | G17: 1 | H17: COSTA AZUL INVESTIMENTOS | I17: PJC Consultoria | J17: 46287 | K17: Enviado | L17: Análise de Crédito | O17: Agendar reunião com fundo
A18: JARDEL | B18: ⁠Consórcio | C18: 9000000 | D18: 0.01 | E18: =D18*C18 -> 90000 | F18: Enviado | G18: 1 | H18: 7 ALDABRAN | I18: ⁠VM Consultoria | J18: 46287 | K18: Enviado | L18: Cadastro | O18: Em analise com o guilherme sobre viabilidade da operação
... A39: PEDRO BRIDI | B39: Capital de Giro | C39: 7000000 | D39: 0.03 | E39: =D39*C39 -> 210000 | F39: Enviado | G39: 1 | H39: 7 ALDABRAN | I39: ⁠VM Consultoria | J39: 46288 | K39: Enviado | L39: Cadastro | O39: Encaminhado para verificar possibilidades
E40: =D40*C40 -> 0
E41: =D41*C41 -> 0
E42: =D42*C42 -> 0
E43: =D43*C43 -> 0
E44: =D44*C44 -> 0
E45: =D45*C45 -> 0
E46: =D46*C46 -> 0
E47: =D47*C47 -> 0
E48: =D48*C48 -> 0
E49: =D49*C49 -> 0
E50: =D50*C50 -> 0
E51: =D51*C51 -> 0
... E276: =D276*C276 -> 0
E277: =IF(OR(C277="",D277=""),"",C277*D277)
E278: =IF(OR(C278="",D278=""),"",C278*D278)
E279: =IF(OR(C279="",D279=""),"",C279*D279)
E280: =IF(OR(C280="",D280=""),"",C280*D280)
E281: =IF(OR(C281="",D281=""),"",C281*D281)
E282: =IF(OR(C282="",D282=""),"",C282*D282)
E283: =IF(OR(C283="",D283=""),"",C283*D283)
E284: =IF(OR(C284="",D284=""),"",C284*D284)
E285: =IF(OR(C285="",D285=""),"",C285*D285)
E286: =IF(OR(C286="",D286=""),"",C286*D286)
E287: =IF(OR(C287="",D287=""),"",C287*D287)
E288: =IF(OR(C288="",D288=""),"",C288*D288)
... E374: =IF(OR(C374="",D374=""),"",C374*D374)

Sheet Pablo Ruan
A6: CLIENTE | B6: OPERAÇÃO | C6: VALOR | D6: FEE | E6: RECEITA | F6: MANDATO | G6: QTD | H6: INSTITUIÇÃO | I6: PARCEIRO INDICADOR | J6: ATUALIZAÇÃO | K6: FLUXO | L6: STATUS | M6: DATA FECHAMENTO | N6: MOTIVO DE RECUSA | O6: OBSERVAÇÃO
A7: RENOVAR | B7: ⁠Antecipação de Recebíveis | C7: 800000 | D7: 0.02 | E7: =D7*C7 -> 16000 | F7: Enviado | G7: 1 | H7: AFFIX FIDC | I7: PJC Consultoria | J7: 46288 | K7: Enviado | L7: Aprovado | O7: ESTA SEM OPERAÇAO
A8: GRUPO MOMENTO | B8: ⁠Antecipação de Recebíveis | C8: 1000000 | D8: 0.015 | E8: =D8*C8 -> 15000 | F8: Não assinado | G8: 1 | H8: RNX FIDIC | I8: PJC Consultoria | J8: 46288 | K8: Enviado | L8: Aprovado | O8: ESTA SEM OPERAÇAO
A9: GRUPO MOMENTO | B9: ⁠Antecipação de Recebíveis | C9: 1500000 | D9: 0.015 | E9: =D9*C9 -> 22500 | F9: Não assinado | G9: 1 | H9: SOMA ASSET | I9: PJC Consultoria | J9: 46288 | K9: Enviado | L9: Aprovado | O9: TRAVOU OPERAÇAO
A10: CB AGRO | B10: ⁠Antecipação de Recebíveis | C10: 500000 | D10: 0.02 | E10: =D10*C10 -> 10000 | F10: Não enviado | G10: 1 | H10: PRIX EMPRESARIAL | I10: PJC Consultoria | J10: 46288 | K10: Enviado | L10: Aprovado | O10: ESTA OPERANDO POUCO
A11: JOAO MARTINS | B11: ⁠Antecipação de Recebíveis | C11: 400000 | D11: 0.02 | E11: =D11*C11 -> 8000 | F11: Não enviado | G11: 1 | H11: AFFIX FIDC | I11: PJC Consultoria | J11: 46288 | K11: Enviado | L11: Análise de Crédito | O11: AGUARD DOC PENDENTE
A12: MS MONTAGENS | B12: ⁠Consultoria | C12: 6000 | E12: =D12*C12 -> 0 | F12: Enviado | G12: 1 | H12: PJC CONSULTORIA | I12: PJC Consultoria | J12: 46288 | K12: Enviado | L12: Cadastro | O12: ESTAMOS EM TRATATIVAS
A13: REI DO PAPELAO | B13: ⁠Antecipação de Recebíveis | C13: 300000 | D13: 0.01 | E13: =D13*C13 -> 3000 | F13: Enviado | G13: 1 | H13: ALX NEGOCIOS | I13: PJC Consultoria | J13: 46288 | K13: Pré-análise | L13: Cadastro | O13: AGUARD DOC PEN/ ABERTURA LIMITE/ ATRASO AFFIX
A14: AGROPECURIA ESTANCIA | B14: ⁠Antecipação de Recebíveis | C14: 300000 | D14: 0.02 | E14: =D14*C14 -> 6000 | F14: Não enviado | G14: 1 | H14: PJC CONSULTORIA | I14: PJC Consultoria | J14: 46257 | K14: Aguardando retorno | L14: Cadastro | O14: DIFICIL COMUNICAÇAO
A15: ROTEC | B15: ⁠Antecipação de Recebíveis | C15: 500000 | D15: 0.02 | E15: =D15*C15 -> 10000 | F15: Não enviado | G15: 1 | H15: PJC CONSULTORIA | I15: PJC Consultoria | J15: 46288 | K15: Aguardando retorno | L15: Cadastro | O15: MARCANDO REUNIAO CALL
A16: TOTAL TEXTIL | B16: ⁠Antecipação de Recebíveis | C16: 300000 | D16: 0.02 | E16: =D16*C16 -> 6000 | F16: Não assinado | G16: 1 | H16: NÃO ATRIBUÍDO | I16: PJC Consultoria | J16: 46288 | K16: Aguardando retorno | L16: Cadastro | O16: AGUARDANDO DOCUMENTAÇAO
A17: INNOVA BRAZIL | B17: ⁠Antecipação de Recebíveis | C17: 3000000 | D17: 0.02 | E17: =D17*C17 -> 60000 | F17: Não assinado | G17: 1 | H17: SOMA ASSET | I17: PJC Consultoria | J17: 46288 | K17: Aguardando retorno | L17: Análise de Crédito | O17: CERTIDAO SIMPLIFICADA
A18: NATIVA AGRICOLA | B18: Cobrança | C18: 6000000 | D18: 0.1 | E18: =D18*C18 -> 600000 | F18: Enviado | G18: 1 | H18: PJC CONSULTORIA | I18: PJC Consultoria | J18: 46288 | K18: Em andamento | L18: Assinatura de Contrato | O18: NAO MANDA A CARTEIRA PARA COBRANÇAS
A19: BELA AGRO | B19: Capital de Giro | C19: 781000 | D19: 0.02 | E19: =D19*C19 -> 15620 | F19: Enviado | G19: 1 | H19: 7 ALDABRAN | I19: PJC Consultoria | J19: 46288 | K19: Enviado | L19: Análise de Crédito | O19: COMPRA DE DIVIDA
A20: PRAT -K | B20: ⁠Antecipação de Recebíveis | C20: 1000000 | D20: 0.02 | E20: =D20*C20 -> 20000 | F20: Não enviado | G20: 1 | H20: NÃO ATRIBUÍDO | I20: PJC Consultoria | J20: 46288 | K20: Não enviado | L20: Cadastro | O20: CALL APOS DIA 23/09
A21: BENINI INDUSTRIA | B21: ⁠Antecipação de Recebíveis | C21: 500000 | D21: 0.02 | E21: =D21*C21 -> 10000 | F21: Não enviado | G21: 1 | H21: NÃO ATRIBUÍDO | I21: PJC Consultoria | J21: 46288 | K21: Não enviado | L21: Cadastro | O21: DIFICIL COMUNICAÇAO
A22: INNOVA BRAZIL | B22: ⁠Antecipação de Recebíveis | C22: 2000000 | D22: 0.02 | E22: =D22*C22 -> 40000 | F22: Não assinado | G22: 1 | H22: INVISTA FIDC | I22: PJC Consultoria | J22: 46288 | K22: Pré-análise | L22: Análise de Crédito
A23: INNOVA BRAZIL | B23: ⁠Antecipação de Recebíveis | C23: 2000000 | D23: 0.02 | E23: =D23*C23 -> 40000 | F23: Não enviado | G23: 1 | H23: JPI FIDC | I23: PJC Consultoria | J23: 46288 | K23: Pré-análise | L23: Análise de Crédito
A24: THP INDUSTRIA | B24: ⁠Antecipação de Recebíveis | C24: 1000000 | D24: 0.02 | E24: =D24*C24 -> 20000 | F24: Enviado | G24: 1 | H24: SAPIENS CAPITAL | I24: PJC Consultoria | J24: 46288 | K24: Pré-análise | L24: Análise de Crédito | O24: REUNIAO MARCADA SEGUNDA FEIRA
A25: THP INDUSTRIA | B25: ⁠Antecipação de Recebíveis | C25: 1000000 | D25: 0.02 | E25: =D25*C25 -> 20000 | F25: Enviado | G25: 1 | H25: INVISTA FIDC | I25: PJC Consultoria | J25: 46288 | K25: Pré-análise | L25: Cadastro
A26: COTRITECH | B26: ⁠Antecipação de Recebíveis | C26: 1000000 | D26: 0.02 | E26: =D26*C26 -> 20000 | F26: Enviado | G26: 1 | H26: SAPIENS CAPITAL | I26: PJC Consultoria | J26: 46288 | K26: Não enviado | L26: Comitê
A27: COTRITECH | B27: ⁠Antecipação de Recebíveis | C27: 1000000 | D27: 0.02 | E27: =D27*C27 -> 20000 | F27: Enviado | G27: 1 | H27: ALX NEGOCIOS | I27: PJC Consultoria | J27: 46288 | K27: Não enviado | L27: Cadastro | O27: ORGANIZANDO DATA PARA REUNIAO
A28: LIPON QUIMICA | B28: ⁠Antecipação de Recebíveis | C28: 1000000 | D28: 0.02 | E28: =D28*C28 -> 20000 | F28: Não enviado | G28: 1 | H28: ALX NEGOCIOS | I28: PJC Consultoria | J28: 46288 | K28: Não enviado | L28: Cadastro
A29: LIPON QUIMICA | B29: ⁠Antecipação de Recebíveis | C29: 1000000 | D29: 0.02 | E29: =D29*C29 -> 20000 | F29: Não enviado | G29: 1 | H29: SAPIENS CAPITAL | I29: PJC Consultoria | J29: 46288 | K29: Não enviado | L29: Cadastro
A30: FRIGORIFICO CHESINI | B30: ⁠Antecipação de Recebíveis | C30: 3000000 | D30: 0.02 | E30: =D30*C30 -> 60000 | F30: Não enviado | G30: 1 | H30: SOMA ASSET | I30: PJC Consultoria | J30: 46288 | K30: Não enviado | L30: Cadastro | O30: REUNIAO PROXIMO MES
A31: ACRILYS TECNOLOGIA | B31: ⁠Antecipação de Recebíveis | C31: 1000000 | D31: 0.02 | E31: =D31*C31 -> 20000 | F31: Não enviado | G31: 1 | H31: NÃO ATRIBUÍDO | I31: PJC Consultoria | J31: 46288 | K31: Não enviado | L31: Cadastro | O31: DIFICIL COMUNICAÇAO
A32: AIRSIDE | B32: ⁠Antecipação de Recebíveis | C32: 500000 | D32: 0.02 | E32: =D32*C32 -> 10000 | F32: Não enviado | G32: 1 | H32: NÃO ATRIBUÍDO | I32: PJC Consultoria | J32: 46288 | K32: Não enviado | L32: Cadastro | O32: MARCANDO REUNIAO
A33: BAP IMPORTS | B33: ⁠Antecipação de Recebíveis | C33: 1000000 | D33: 0.02 | E33: =D33*C33 -> 20000 | F33: Não enviado | G33: 1 | H33: NÃO ATRIBUÍDO | I33: PJC Consultoria | J33: 46288 | K33: Não enviado | L33: Cadastro | O33: REUNIAOSEXTA PRESENCIAL 09:00 HRS
A34: RENOVAR | B34: Capital de Giro | C34: 350000 | D34: 0.02 | E34: =D34*C34 -> 7000 | F34: Enviado | G34: 1 | H34: CASHME | I34: PJC Consultoria | J34: 46288 | K34: Enviado | L34: Cadastro | O34: AGUARD DOC PENDENTE
A35: FRIGOGYN | B35: Capital de Giro | C35: 500000 | D35: 0.02 | E35: =D35*C35 -> 10000 | F35: Enviado | G35: 1 | H35: TRUST CAPITAL | I35: PJC Consultoria | J35: 46288 | K35: Não enviado | L35: Cadastro | O35: AGUARDANDO PLATAFORMA
A36: FRIGOGYN | B36: Capital de Giro | C36: 500000 | D36: 0.02 | E36: =D36*C36 -> 10000 | F36: Enviado | G36: 1 | H36: 7 ALDABRAN | I36: PJC Consultoria | J36: 46288 | K36: Não enviado | L36: Cadastro
A37: LABARCA | B37: ⁠Antecipação de Recebíveis | C37: 1000000 | D37: 0.02 | E37: =D37*C37 -> 20000 | F37: Não enviado | G37: 1 | H37: NÃO ATRIBUÍDO | I37: PJC Consultoria | J37: 46288 | K37: Não enviado | L37: Cadastro | O37: PRIMEIRO CONTATO
A38: INNOVA BRAZIL | B38: ⁠Antecipação de Recebíveis | C38: 1000000 | D38: 0.02 | E38: =D38*C38 -> 20000 | F38: Não enviado | G38: 1 | H38: DIAMOND | I38: PJC Consultoria | J38: 46288 | K38: Enviado | L38: Cadastro
A39: THP INDUSTRIA | B39: ⁠Antecipação de Recebíveis | C39: 1000000 | D39: 0.025 | E39: =D39*C39 -> 25000 | F39: Enviado | G39: 1 | H39: DIAMOND | I39: PJC Consultoria | J39: 46287 | K39: Enviado | L39: Cadastro
A40: RAPIDO IGREJINHA | B40: ⁠Antecipação de Recebíveis | C40: 500000 | D40: 0.02 | E40: =D40*C40 -> 10000 | F40: Não enviado | G40: 1 | H40: NÃO ATRIBUÍDO | I40: PJC Consultoria | J40: 46288 | K40: Não enviado | L40: Cadastro
A41: PARABONI FERRAMENTAS | B41: ⁠Antecipação de Recebíveis | C41: 1000000 | D41: 0.02 | E41: =D41*C41 -> 20000 | F41: Não enviado | G41: 1 | H41: NÃO ATRIBUÍDO | I41: PJC Consultoria | J41: 46288 | K41: Não enviado | L41: Cadastro
E42: =D42*C42 -> 0
E43: =D43*C43 -> 0
E44: =D44*C44 -> 0
E45: =D45*C45 -> 0
...

Sheet André Pullig
A6: CLIENTE | B6: OPERAÇÃO | C6: VALOR | D6: FEE | E6: RECEITA | F6: MANDATO | G6: QTD | H6: INSTITUIÇÃO | I6: PARCEIRO INDICADOR | J6: ATUALIZAÇÃO | K6: FLUXO | L6: STATUS | M6: DATA FECHAMENTO | N6: MOTIVO DE RECUSA | O6: OBSERVAÇÃO
A7: LUKMAM - 38.249.690/0001-90 | B7: ⁠Antecipação de Recebíveis | C7: 300000 | D7: 0.03 | E7: =D7*C7 -> 9000 | F7: Assinado | G7: 1 | H7: NÃO ATRIBUÍDO | I7: ⁠Blue Score | J7: 46288 | K7: Em andamento | L7: Reprovado | M7: 46288 | N7: Outro (detalhar na observação) | O7: Não possui documentação
A8: NUTRIMAX - 53.039.803/0001-16 | B8: ⁠Antecipação de Recebíveis | C8: 500000 | D8: 0.03 | E8: =D8*C8 -> 15000 | F8: Assinado | G8: 1 | H8: NÃO ATRIBUÍDO | I8: ⁠Blue Score | J8: 46288 | K8: Em andamento | L8: Reprovado | M8: 46288 | O8: FALTANDO DOCUMENTO - RAFAEL
A9: GUILHERME - 37.752.853/0001-90 | B9: ⁠Antecipação de Recebíveis | C9: 300000 | D9: 0.03 | E9: =D9*C9 -> 9000 | F9: Enviado | G9: 1 | H9: NÃO ATRIBUÍDO | I9: Astrum Finance | J9: 46288 | K9: Em andamento | L9: Cadastro | O9: FALTANDO DOCUMENTO - POLIANA ASTRUM
A10: BARRIERE - 51.544.166/0001-00 | B10: ⁠Antecipação de Recebíveis | C10: 300000 | D10: 0.03 | E10: =D10*C10 -> 9000 | F10: Assinado | G10: 1 | H10: 7 ALDABRAN | I10: ⁠Blue Score | J10: 46288 | K10: Em andamento | L10: Análise de Crédito | O10: AGUARDANDO ALFREDO
A11: RIBEIRO - 24.467.220/0001-98 | B11: ⁠Antecipação de Recebíveis | C11: 300000 | D11: 0.03 | E11: =D11*C11 -> 9000 | F11: Assinado | G11: 1 | H11: 7 ALDABRAN | I11: ⁠Blue Score | J11: 46288 | K11: Em andamento | L11: Análise de Crédito | O11: AGUARDANDO REUNIAO
A12: PLUMEY - 01.326.832/0001-65 | B12: ⁠Antecipação de Recebíveis | C12: 500000 | D12: 0.03 | E12: =D12*C12 -> 15000 | F12: Enviado | G12: 1 | H12: NÃO ATRIBUÍDO | I12: Astrum Finance | J12: 46288 | K12: Em andamento | L12: Cadastro | O12: FALTANDO DOCUMENTO - POLIANA ASTRUM
A13: ALBIERE TRANSPORTES - ALFA | B13: ⁠Antecipação de Recebíveis | C13: 600000 | D13: 0.0075 | E13: =D13*C13 -> 4500 | F13: Enviado | G13: 1 | H13: RNX FIDIC | I13: ⁠Blue Score | J13: 46288 | K13: Enviado | L13: Finalizado | M13: 46274 | O13: AGUARDANDO PROPOSTA
A14: ALBIERE TRANSPORTES - ALFA | B14: ⁠Antecipação de Recebíveis | C14: 5000000 | D14: 0.01 | E14: =D14*C14 -> 50000 | F14: Enviado | G14: 1 | H14: SOMA ASSET | I14: ⁠Blue Score | J14: 46288 | K14: Em andamento | L14: Cadastro | O14: AGUARDANDO PROPOSTA
A15: DALBIERE TRANSPORTES - ALFA | B15: ⁠Antecipação de Recebíveis | C15: 5000000 | D15: 0.01 | E15: =D15*C15 -> 50000 | F15: Enviado | G15: 1 | H15: SOMA ASSET | I15: ⁠Blue Score | J15: 46288 | K15: Em andamento | L15: Cadastro | O15: AGUARDANDO PROPOSTA
A16: PARQUE ENGENHARIA | B16: ⁠Antecipação de Recebíveis | C16: 150000 | D16: 0 | E16: =D16*C16 -> 0 | F16: Assinado | G16: 1 | H16: GOIAS BANK | I16: PJC Consultoria | J16: 46288 | K16: Em andamento | L16: Finalizado | M16: 46274 | O16: JÁ ESTA OPERANDO
A17: PARQUE ENGENHARIA | B17: ⁠FGI | C17: 500000 | D17: 0.05 | E17: =D17*C17 -> 25000 | F17: Assinado | G17: 1 | H17: 7 ALDABRAN | I17: PJC Consultoria | J17: 46288 | K17: Em andamento | L17: Análise de Crédito
A18: PARQUE ENGENHARIA | B18: ⁠Antecipação de Recebíveis | C18: 300000 | D18: 0 | E18: =D18*C18 -> 0 | F18: Assinado | G18: 1 | H18: ALX NEGOCIOS | I18: PJC Consultoria | J18: 46288 | K18: Em andamento | L18: Cadastro | O18: AGUARDANDO LIMPAR O NOME
A19: LAP COSMETICOS | B19: ⁠Antecipação de Recebíveis | C19: 4000000 | D19: 0.03 | E19: =D19*C19 -> 120000 | F19: Não enviado | G19: 1 | H19: SOMA ASSET | I19: PJC Consultoria | J19: 46288 | K19: Não enviado | L19: Cadastro | O19: AGUARDANDO DOCUMENTOS
A20: LAP COSMETICOS | B20: ⁠Antecipação de Recebíveis | C20: 1500000 | D20: 0.03 | E20: =D20*C20 -> 45000 | F20: Não enviado | G20: 1 | H20: RNX FIDIC | I20: PJC Consultoria | J20: 46288 | K20: Não enviado | L20: Cadastro
A21: LAP COSMETICOS | B21: ⁠Antecipação de Recebíveis | C21: 1500000 | D21: 0.03 | E21: =D21*C21 -> 45000 | F21: Não enviado | G21: 1 | H21: AFFIX FIDC | I21: PJC Consultoria | J21: 46288 | K21: Não enviado | L21: Cadastro
A22: SAFRA BRASIL 34.984.590/0001-56 | B22: ⁠Antecipação de Recebíveis | C22: 1000000 | D22: 0.05 | E22: =D22*C22 -> 50000 | F22: Assinado | G22: 1 | H22: 7 ALDABRAN | I22: ⁠Blue Score | J22: 46288 | K22: Em andamento | L22: Cadastro | O22: AGUARDANDO DOCUMENTOS
A23: SAFRA BRASIL 34.984.590/0002-37 | B23: ⁠Antecipação de Recebíveis | C23: 1000000 | D23: 0.05 | E23: =D23*C23 -> 50000 | F23: Assinado | G23: 1 | H23: 7 ALDABRAN | I23: ⁠Blue Score | J23: 46288 | K23: Em andamento | L23: Cadastro | O23: AGUARDANDO DOCUMENTOS
A24: SAFRA BRASIL 05.052.142/0001-16 | B24: ⁠Antecipação de Recebíveis | C24: 1000000 | D24: 0.05 | E24: =D24*C24 -> 50000 | F24: Assinado | G24: 1 | H24: 7 ALDABRAN | I24: ⁠Blue Score | J24: 46288 | K24: Em andamento | L24: Cadastro | O24: AGUARDANDO DOCUMENTOS
A25: CMX COMERCIO 52.961.756/0001-09 | B25: Capital de Giro | C25: 3000000 | D25: 0.05 | E25: =D25*C25 -> 150000 | F25: Não enviado | G25: 1 | H25: 7 ALDABRAN | I25: ⁠Blue Score | J25: 46288 | K25: Enviado | L25: Cadastro | O25: AGUARDANDO DOCUMENTOS
A26: MS COMPRA E VENDA 53.241.901/0001-31 | B26: Pronampe | C26: 500000 | D26: 0.15 | E26: =D26*C26 -> 75000 | F26: Assinado | G26: 1 | H26: 7 ALDABRAN | I26: Sandro | J26: 46288 | K26: Em andamento | L26: Cadastro | O26: AGUARDANDO DOCUMENTOS
A27: MS COMPRA E VENDA 53.241.901/0001-31 | B27: ⁠FGI | C27: 300000 | D27: 0.1 | E27: =D27*C27 -> 30000 | F27: Assinado | G27: 1 | H27: PS FINANCE | I27: Sandro | J27: 46288 | K27: Em andamento | L27: Cadastro
A28: AGRONORTE - 30.480.055/0001-07 | B28: Pronampe | C28: 500000 | D28: 0.15 | E28: =D28*C28 -> 75000 | F28: Assinado | G28: 1 | H28: 7 ALDABRAN | I28: Sandro | J28: 46288 | K28: Em andamento | L28: Cadastro | O28: AGUARDANDO DOCUMENTOS
A29: AGRONORTE - 30.480.055/0001-07 | B29: ⁠FGI | C29: 500000 | D29: 0.1 | E29: =D29*C29 -> 50000 | F29: Assinado | G29: 1 | H29: PS FINANCE | I29: Sandro | J29: 46288 | K29: Em andamento | L29: Cadastro
A30: PRIME SERVIÇOS - 40.905.651/0001-45 | B30: Pronampe | C30: 500000 | D30: 0.15 | E30: =D30*C30 -> 75000 | F30: Assinado | G30: 1 | H30: 7 ALDABRAN | I30: Sandro | J30: 46288 | K30: Em andamento | L30: Cadastro | O30: AGUARDANDO DOCUMENTOS
A31: BIOCRIM - 58.352.399/0001-50 | B31: ⁠FGI | C31: 1500000 | D31: 0.05 | E31: =D31*C31 -> 75000 | F31: Não enviado | G31: 1 | H31: 7 ALDABRAN | I31: Astrum Finance | J31: 46288 | K31: Em andamento | L31: Cadastro | O31: AGUARDANDO DOCUMENTOS
A32: PACIFICO COMERCIAL DE ALIMENTOS E PRODUTOS DE LIMPEZA LTDA | B32: Pronampe | C32: 500000 | D32: 0.15 | E32: =D32*C32 -> 75000 | F32: Assinado | G32: 1 | H32: 7 ALDABRAN | I32: Sandro | J32: 46288 | K32: Em andamento | L32: Cadastro | O32: AGUARDANDO DOCUMENTOS
A33: C2C COMÉRCIO DE ALIMENTOS LTDA | B33: Pronampe | C33: 500000 | D33: 0.15 | E33: =D33*C33 -> 75000 | F33: Assinado | G33: 1 | H33: 7 ALDABRAN | I33: Sandro | J33: 46288 | K33: Em andamento | L33: Cadastro | O33: AGUARDANDO DOCUMENTOS
A34: CABRAL CICLA COMERCIO VAREJISTA DE MATERIAIS DE CONSTRUÇÃO LTDA | B34: Pronampe | C34: 500000 | D34: 0.15 | E34: =D34*C34 -> 75000 | F34: Assinado | G34: 1 | H34: 7 ALDABRAN | I34: Sandro | J34: 46288 | K34: Em andamento | L34: Cadastro | O34: AGUARDANDO DOCUMENTOS
A35: TIO PNEUS COMERCIO VAREJISTA - 50.152.219/0001-84 | B35: ⁠Antecipação de Recebíveis | C35: 200000 | D35: 0.03 | E35: =D35*C35 -> 6000 | F35: Assinado | G35: 1 | H35: 7 ALDABRAN | I35: Walber | J35: 46288 | K35: Em andamento | L35: Cadastro | O35: AGUARDANDO DOCUMENTOS
A36: TIO PNEUS COMERCIO VAREJISTA - 50.152.219/0001-84 | B36: ⁠Antecipação de Recebíveis | C36: 200000 | D36: 0.03 | E36: =D36*C36 -> 6000 | F36: Assinado | G36: 1 | H36: AFFIX FIDC | I36: Walber | J36: 46288 | K36: Em andamento | L36: Finalizado | M36: 46288 | O36: AGUARDANDO DOCUMENTOS
A37: TIO PNEUS COMERCIO VAREJISTA - 50.152.219/0001-84 | B37: ⁠Antecipação de Recebíveis | C37: 200000 | D37: 0.03 | E37: =D37*C37 -> 6000 | F37: Assinado | G37: 1 | H37: RNX FIDIC | I37: Walber | J37: 46288 | K37: Em andamento | L37: Reprovado | O37: AGUARDANDO DOCUMENTOS
A38: TIO PNEUS COMERCIO VAREJISTA - 50.152.219/0001-84 | B38: ⁠Antecipação de Recebíveis | C38: 200000 | D38: 0.03 | E38: =D38*C38 -> 6000 | F38: Assinado | G38: 1 | H38: SAPIENS CAPITAL | I38: Walber | J38: 46288 | K38: Em andamento | L38: Cadastro
A39: SERGIO GONCALVES DE OLIVEIRA | B39: Capital de Giro | C39: 10000000 | D39: 0.025 | E39: =D39*C39 -> 250000 | F39: Assinado | G39: 1 | H39: 7 ALDABRAN | I39: ⁠PS Finance | J39: 46286 | K39: Em andamento | L39: Cadastro
A40: LINDOMAR DA COSTA LIMA | B40: ⁠Home Equity | C40: 4000000 | D40: 0.05 | E40: =D40*C40 -> 200000 | F40: Não assinado | G40: 1 | H40: 7 ALDABRAN | I40: ⁠Blue Score | J40: 46286 | K40: Pré-análise | L40: Cadastro | M40: Aguardando documentos
E41: =D41*C41 -> 0
E42: =D42*C42 -> 0
E43: =D43*C43 -> 0
E44: =D44*C44 -> 0
E45: =D45*C45 -> 0
...

Sheet Betania Ribeiro
A6: CLIENTE | B6: OPERAÇÃO | C6: VALOR | D6: FEE | E6: RECEITA | F6: MANDATO | G6: QTD | H6: INSTITUIÇÃO | I6: PARCEIRO INDICADOR | J6: ATUALIZAÇÃO | K6: FLUXO | L6: STATUS | M6: DATA FECHAMENTO | N6: MOTIVO DE RECUSA | O6: OBSERVAÇÃO
A7: JOTAAGRO PRODUCOES E COMERCIALIZACOES AGRICOLAS LTDA | B7: Custeio | C7: 8000000 | D7: 0.06 | E7: =D7*C7 -> 480000 | F7: Assinado | G7: 1 | H7: 7 ALDABRAN | J7: 46288 | K7: Aguardando retorno | L7: já passou em comitê e aguardando visita tecnica | O7: doc. com Guilherme - op. agro
A8: GILMAR AUGUSTO GOMES | B8: ⁠Credito Rural | C8: 10000000 | D8: 0.06 | E8: =D8*C8 -> 600000 | F8: Assinado | G8: 1 | H8: 7 ALDABRAN | J8: 46288 | K8: Pré-análise | L8: Análise de Crédito
E9: =D9*C9 -> 0
E10: =D10*C10 -> 0
E11: =D11*C11 -> 0
E12: =D12*C12 -> 0
E13: =D13*C13 -> 0
E14: =D14*C14 -> 0
E15: =D15*C15 -> 0
E16: =D16*C16 -> 0
E17: =D17*C17 -> 0
E18: =D18*C18 -> 0
E19: =D19*C19 -> 0
E20: =D20*C20 -> 0
... E292: =D292*C292 -> 0
E293: =IF(OR(C293="",D293=""),"",C293*D293)
E294: =IF(OR(C294="",D294=""),"",C294*D294)
E295: =IF(OR(C295="",D295=""),"",C295*D295)
E296: =IF(OR(C296="",D296=""),"",C296*D296)
E297: =IF(OR(C297="",D297=""),"",C297*D297)
E298: =IF(OR(C298="",D298=""),"",C298*D298)
E299: =IF(OR(C299="",D299=""),"",C299*D299)
E300: =IF(OR(C300="",D300=""),"",C300*D300)
E301: =IF(OR(C301="",D301=""),"",C301*D301)
E302: =IF(OR(C302="",D302=""),"",C302*D302)
E303: =IF(OR(C303="",D303=""),"",C303*D303)
E304: =IF(OR(C304="",D304=""),"",C304*D304)
... E400: =IF(OR(C400="",D400=""),"",C400*D400)

Sheet PARAMETROS
A1: PARÂMETROS — LISTAS OFICIAIS
A2: As abas dos gerentes puxam daqui. Para incluir um item, escreva na primeira linha vazia da coluna: a lista suspensa reconhece sozinha.
A3: Itens com * ainda precisam de confirmação (nome ou existência). Não apague item já usado: troque a Situação para Inativo.
A5: PARCEIRO (INSTITUIÇÃO) | B5: Situação | D5: GERENTE | E5: Situação | G5: TIPO DE OPERAÇÃO | H5: Situação | J5: STATUS | K5: Situação | M5: FLUXO | N5: Situação | P5: MANDATO | Q5: Situação | S5: ORIGEM | T5: Situação | V5: MOTIVO DE RECUSA | W5: Situação
A6: 7 ALDABRAN | B6: Ativo | D6: ⁠André Pullig | E6: Ativo | G6: Capital de Giro | H6: Ativo | J6: Cadastro | K6: Ativo | M6: Não enviado | N6: Ativo | P6: Não enviado | Q6: Ativo | S6: PJC Consultoria | T6: Ativo | V6: Restrição cadastral (Serasa / protesto) | W6: Ativo
A7: ACREDITAR FIDC | B7: Ativo | D7: ⁠Betania Ribeiro | E7: Ativo | G7: ⁠Antecipação de Recebíveis | H7: Ativo | J7: Análise de Crédito | K7: Ativo | M7: Pré-análise | N7: Ativo | P7: Enviado | Q7: Ativo | S7: ⁠LOBE Contabilidade | T7: Ativo | V7: Faturamento insuficiente | W7: Ativo
A8: AFFIX FIDC | B8: Ativo | D8: ⁠João Pullig | E8: Ativo | G8: ⁠Pro-Soluto | H8: Ativo | J8: Comitê | K8: Ativo | M8: Enviado | N8: Ativo | P8: Assinado | Q8: Ativo | S8: ⁠Sapiens Capital | T8: Ativo | V8: Garantia insuficiente | W8: Ativo
A9: ALIA CAPITAL | B9: Ativo | D9: Kaio Dias | E9: Ativo | G9: ⁠Credito Rural | H9: Ativo | J9: Aprovação | K9: Ativo | M9: Em andamento | N9: Ativo | P9: Não assinado | Q9: Ativo | S9: ⁠Alia Capital | T9: Ativo | V9: Documentação incompleta | W9: Ativo
A10: ALX NEGOCIOS | B10: Ativo | D10: ⁠Pablo Ruan | E10: Ativo | G10: ⁠Consórcio | H10: Ativo | J10: Assinatura de Contrato | K10: Ativo | M10: Aguardando retorno | N10: Ativo | S10: ⁠Blue Score | T10: Ativo | V10: Fora do perfil da instituição | W10: Ativo
A11: APX Finance | B11: Ativo | D11: ⁠Rafael Nedino | E11: Ativo | G11: ⁠FGI | H11: Ativo | J11: Aprovado | K11: Ativo | S11: ⁠Integra Negócios | T11: Ativo | V11: Outro (detalhar na observação) | W11: Ativo
A12: AR3 CAPITAL | B12: Ativo | G12: ⁠Home Equity | H12: Ativo | J12: Reprovado | K12: Ativo | S12: ⁠VM Consultoria | T12: Ativo
A13: ASTRUM FINANCEIRA | B13: Ativo | G13: ⁠CRA | H13: Ativo | J13: Finalizado | K13: Ativo | S13: ⁠LA Advogados | T13: Ativo
A14: BANCO BCG | B14: Ativo | G14: ⁠CRI | H14: Ativo | S14: ⁠PS Finance | T14: Ativo
A15: BANCO BMG | B15: Ativo | G15: ⁠CPR-F | H15: Ativo | S15: ⁠MB Finance | T15: Ativo
A16: BANCO BS2 | B16: Ativo | G16: ⁠Cambio | H16: Ativo | S16: ⁠Valor Investimentos | T16: Ativo
A17: BANCO BSB | B17: Ativo | G17: ⁠Antecipação de Contrato | H17: Ativo | S17: Astrum Finance | T17: Ativo
A18: BANCO BTG | B18: Ativo | G18: ⁠Seguro | H18: Ativo | S18: Diamond | T18: Ativo
A19: BANCO BV | B19: Ativo | G19: ⁠Limpa Nome | H19: Ativo
A20: BANCO C6 | B20: Ativo | G20: ⁠Antecipação SUS | H20: Ativo
A21: BANCO CNH | B21: Ativo | G21: ⁠Valuation | H21: Ativo
A22: BANCO DA AMAZONIA | B22: Ativo | G22: ⁠Reformulação Contábil | H22: Ativo
A23: BANCO DO BRASIL | B23: Ativo | G23: ⁠Financiamento de Máquinas | H23: Ativo
A24: BANCO DO NORDESTE | B24: Ativo | G24: ⁠Financiamento de Veículos | H24: Ativo
A25: BANCO INTER | B25: Ativo | G25: ⁠Financiamento de Imóvel | H25: Ativo
A26: BANCO ORIGINAL | B26: Ativo | G26: ⁠FCO | H26: Ativo
A27: BANCO SAFRA | B27: Ativo | G27: ⁠BNDES | H27: Ativo
A28: BANCO SOFISA | B28: Ativo | G28: ⁠Auto Equity | H28: Ativo
A29: BANRISUL | B29: Ativo | G29: ⁠Plano de Saúde | H29: Ativo
A30: BLUE SCORE | B30: Ativo | G30: ⁠ACC | H30: Ativo
... A38: DAVOS FIDC | B38: Ativo | G38: Investimento | H38: Ativo
A39: DAYCOVAL | B39: Ativo
A40: DMX CAPITAL | B40: Ativo
A41: FIRMA CAPITAL | B41: Ativo
A42: GOIAS BANK | B42: Ativo
A43: GUARA SECURITIZADORA | B43: Ativo
A44: GUPRO SIFRA | B44: Ativo
A45: INTRABANK | B45: Ativo
A46: INVISTA FIDC | B46: Ativo
A47: ITAU | B47: Ativo
A48: ITAU BBA | B48: Ativo
...

Sheet DASHBOARD
A1: DASHBOARD — VISÃO GERAL
A2: Consolidado das abas dos gerentes. Tudo se atualiza sozinho ao preencher as operações — não há botão a apertar.
A4: RESUMO GERAL
A5: Operações ativas | C5: Em negociação | E5: Volume aprovado | G5: Receita aprovada
A6: =COUNTIFS('André Pullig'!$A$7:$A$396,"<>")+COUNTIFS('Betania Ribeiro'!$A$7:$A$400,"<>")+COUNTIFS('João Pullig'!$A$7:$A$385,"<>")+COUNTIFS('Kaio Dias'!$A$7:$A$374,"<>")+COUNTIFS('Pablo Ruan'!$A$7:$A$382,"<>")+COUNTIFS(#REF!,"<>") -> #REF! | C6: =SUMIFS('André Pullig'!$C$7:$C$396,'André Pullig'!$L$7:$L$396,"<>Aprovado",'André Pullig'!$L$7:$L$396,"<>Reprovado",'André Pullig'!$L$7:$L$396,"<>")+SUMIFS('Betania Ribeiro'!$C$7:$C$400,'Betania Ribeiro'!$L$7:$L$400,"<>Aprovado",'Betania Ribeiro'!$L$7:$L$400,"<>Reprovado",'Betania Ribeiro'!$L$7:$L$400,"<>")+SUMIFS('João Pullig'!$C$7:$C$385,'João Pullig'!$L$7:$L$385,"<>Aprovado",'João Pullig'!$L$7:$L$385,"<>Reprovado",'João Pullig'!$L$7:$L$385,"<>")+SUMIFS('Kaio Dias'!$C$7:$C$374,'Kaio Dias'!$L$7:$L$374,"<>Aprovado",'Kaio Dias'!$L$7:$L$374,"<>Reprovado",'Kaio Dias'!$L$7:$L$374,"<>")+SUMIFS('Pablo Ruan'!$C$7:$C$382,'Pablo Ruan'!$L$7:$L$382,"<>Aprovado",'Pablo Ruan'!$L$7:$L$382,"<>Reprovado",'Pablo Ruan'!$L$7:$L$382,"<>")+SUMIFS(#REF!,#REF!,"<>Aprovado",#REF!,"<>Reprovado",#REF!,"<>") -> #REF! | E6: =SUMIFS('André Pullig'!$C$7:$C$396,'André Pullig'!$L$7:$L$396,"Aprovado")+SUMIFS('Betania Ribeiro'!$C$7:$C$400,'Betania Ribeiro'!$L$7:$L$400,"Aprovado")+SUMIFS('João Pullig'!$C$7:$C$385,'João Pullig'!$L$7:$L$385,"Aprovado")+SUMIFS('Kaio Dias'!$C$7:$C$374,'Kaio Dias'!$L$7:$L$374,"Aprovado")+SUMIFS('Pablo Ruan'!$C$7:$C$382,'Pablo Ruan'!$L$7:$L$382,"Aprovado")+SUMIFS(#REF!,#REF!,"Aprovado") -> #REF! | G6: =SUMIFS('André Pullig'!$E$7:$E$396,'André Pullig'!$L$7:$L$396,"Aprovado")+SUMIFS('Betania Ribeiro'!$E$7:$E$400,'Betania Ribeiro'!$L$7:$L$400,"Aprovado")+SUMIFS('João Pullig'!$E$7:$E$385,'João Pullig'!$L$7:$L$385,"Aprovado")+SUMIFS('Kaio Dias'!$E$7:$E$374,'Kaio Dias'!$L$7:$L$374,"Aprovado")+SUMIFS('Pablo Ruan'!$E$7:$E$382,'Pablo Ruan'!$L$7:$L$382,"Aprovado")+SUMIFS(#REF!,#REF!,"Aprovado") -> #REF!
A8: POR GERENTE
A9: Gerente | B9: Operações | C9: Sem valor | D9: Em negociação | E9: Volume aprovado | F9: Receita aprovada | G9: % da receita
A10: André Pullig | B10: =COUNTIFS('André Pullig'!$A$7:$A$396,"<>") -> 34 | C10: =COUNTIFS('André Pullig'!$A$7:$A$396,"<>",'André Pullig'!$C$7:$C$396,"") -> 0 | D10: =SUMIFS('André Pullig'!$C$7:$C$396,'André Pullig'!$L$7:$L$396,"<>Aprovado",'André Pullig'!$L$7:$L$396,"<>Reprovado",'André Pullig'!$L$7:$L$396,"<>") -> 45850000 | E10: =SUMIFS('André Pullig'!$C$7:$C$396,'André Pullig'!$L$7:$L$396,"Aprovado") -> 0 | F10: =SUMIFS('André Pullig'!$E$7:$E$396,'André Pullig'!$L$7:$L$396,"Aprovado") -> 0 | G10: =IF(N($F$16)=0,"",F10/$F$16) -> #REF!
A11: Betania Ribeiro | B11: =COUNTIFS('Betania Ribeiro'!$A$7:$A$400,"<>") -> 2 | C11: =COUNTIFS('Betania Ribeiro'!$A$7:$A$400,"<>",'Betania Ribeiro'!$C$7:$C$400,"") -> 0 | D11: =SUMIFS('Betania Ribeiro'!$C$7:$C$400,'Betania Ribeiro'!$L$7:$L$400,"<>Aprovado",'Betania Ribeiro'!$L$7:$L$400,"<>Reprovado",'Betania Ribeiro'!$L$7:$L$400,"<>") -> 18000000 | E11: =SUMIFS('Betania Ribeiro'!$C$7:$C$400,'Betania Ribeiro'!$L$7:$L$400,"Aprovado") -> 0 | F11: =SUMIFS('Betania Ribeiro'!$E$7:$E$400,'Betania Ribeiro'!$L$7:$L$400,"Aprovado") -> 0 | G11: =IF(N($F$16)=0,"",F11/$F$16) -> #REF!
A12: João Pullig | B12: =COUNTIFS('João Pullig'!$A$7:$A$385,"<>") -> 31 | C12: =COUNTIFS('João Pullig'!$A$7:$A$385,"<>",'João Pullig'!$C$7:$C$385,"") -> 0 | D12: =SUMIFS('João Pullig'!$C$7:$C$385,'João Pullig'!$L$7:$L$385,"<>Aprovado",'João Pullig'!$L$7:$L$385,"<>Reprovado",'João Pullig'!$L$7:$L$385,"<>") -> 180100000 | E12: =SUMIFS('João Pullig'!$C$7:$C$385,'João Pullig'!$L$7:$L$385,"Aprovado") -> 2000000 | F12: =SUMIFS('João Pullig'!$E$7:$E$385,'João Pullig'!$L$7:$L$385,"Aprovado") -> 65000 | G12: =IF(N($F$16)=0,"",F12/$F$16) -> #REF!
A13: Kaio Dias | B13: =COUNTIFS('Kaio Dias'!$A$7:$A$374,"<>") -> 33 | C13: =COUNTIFS('Kaio Dias'!$A$7:$A$374,"<>",'Kaio Dias'!$C$7:$C$374,"") -> 0 | D13: =SUMIFS('Kaio Dias'!$C$7:$C$374,'Kaio Dias'!$L$7:$L$374,"<>Aprovado",'Kaio Dias'!$L$7:$L$374,"<>Reprovado",'Kaio Dias'!$L$7:$L$374,"<>") -> 132006000 | E13: =SUMIFS('Kaio Dias'!$C$7:$C$374,'Kaio Dias'!$L$7:$L$374,"Aprovado") -> 777242 | F13: =SUMIFS('Kaio Dias'!$E$7:$E$374,'Kaio Dias'!$L$7:$L$374,"Aprovado") -> 19431.05 | G13: =IF(N($F$16)=0,"",F13/$F$16) -> #REF!
A14: Pablo Ruan | B14: =COUNTIFS('Pablo Ruan'!$A$7:$A$382,"<>") -> 35 | C14: =COUNTIFS('Pablo Ruan'!$A$7:$A$382,"<>",'Pablo Ruan'!$C$7:$C$382,"") -> 0 | D14: =SUMIFS('Pablo Ruan'!$C$7:$C$382,'Pablo Ruan'!$L$7:$L$382,"<>Aprovado",'Pablo Ruan'!$L$7:$L$382,"<>Reprovado",'Pablo Ruan'!$L$7:$L$382,"<>") -> 34437000 | E14: =SUMIFS('Pablo Ruan'!$C$7:$C$382,'Pablo Ruan'!$L$7:$L$382,"Aprovado") -> 3800000 | F14: =SUMIFS('Pablo Ruan'!$E$7:$E$382,'Pablo Ruan'!$L$7:$L$382,"Aprovado") -> 63500 | G14: =IF(N($F$16)=0,"",F14/$F$16) -> #REF!
A15: Rafael Nedino | B15: =COUNTIFS(#REF!,"<>") -> #REF! | C15: =COUNTIFS(#REF!,"<>",#REF!,"") -> #REF! | D15: =SUMIFS(#REF!,#REF!,"<>Aprovado",#REF!,"<>Reprovado",#REF!,"<>") -> #REF! | E15: =SUMIFS(#REF!,#REF!,"Aprovado") -> #REF! | F15: =SUMIFS(#REF!,#REF!,"Aprovado") -> #REF! | G15: =IF(N($F$16)=0,"",F15/$F$16) -> #REF!
A16: TOTAL | B16: =SUM(B10:B15) -> #REF! | C16: =SUM(C10:C15) -> #REF! | D16: =SUM(D10:D15) -> #REF! | E16: =SUM(E10:E15) -> #REF! | F16: =SUM(F10:F15) -> #REF! | G16: =SUM(G10:G15) -> #REF!
A18: SITUAÇÃO DAS OPERAÇÕES
A19: Status | B19: Operações | C19: Volume | D19: % do volume
A20: Cadastro | B20: =COUNTIFS('André Pullig'!$L$7:$L$396,"Cadastro")+COUNTIFS('Betania Ribeiro'!$L$7:$L$400,"Cadastro")+COUNTIFS('João Pullig'!$L$7:$L$385,"Cadastro")+COUNTIFS('Kaio Dias'!$L$7:$L$374,"Cadastro")+COUNTIFS('Pablo Ruan'!$L$7:$L$382,"Cadastro")+COUNTIFS(#REF!,"Cadastro") -> #REF! | C20: =SUMIFS('André Pullig'!$C$7:$C$396,'André Pullig'!$L$7:$L$396,"Cadastro")+SUMIFS('Betania Ribeiro'!$C$7:$C$400,'Betania Ribeiro'!$L$7:$L$400,"Cadastro")+SUMIFS('João Pullig'!$C$7:$C$385,'João Pullig'!$L$7:$L$385,"Cadastro")+SUMIFS('Kaio Dias'!$C$7:$C$374,'Kaio Dias'!$L$7:$L$374,"Cadastro")+SUMIFS('Pablo Ruan'!$C$7:$C$382,'Pablo Ruan'!$L$7:$L$382,"Cadastro")+SUMIFS(#REF!,#REF!,"Cadastro") -> #REF! | D20: =IF(SUM($C$20:$C$26)=0,"",C20/SUM($C$20:$C$26)) -> #REF!
A21: Análise de Crédito | B21: =COUNTIFS('André Pullig'!$L$7:$L$396,"Análise de Crédito")+COUNTIFS('Betania Ribeiro'!$L$7:$L$400,"Análise de Crédito")+COUNTIFS('João Pullig'!$L$7:$L$385,"Análise de Crédito")+COUNTIFS('Kaio Dias'!$L$7:$L$374,"Análise de Crédito")+COUNTIFS('Pablo Ruan'!$L$7:$L$382,"Análise de Crédito")+COUNTIFS(#REF!,"Análise de Crédito") -> #REF! | C21: =SUMIFS('André Pullig'!$C$7:$C$396,'André Pullig'!$L$7:$L$396,"Análise de Crédito")+SUMIFS('Betania Ribeiro'!$C$7:$C$400,'Betania Ribeiro'!$L$7:$L$400,"Análise de Crédito")+SUMIFS('João Pullig'!$C$7:$C$385,'João Pullig'!$L$7:$L$385,"Análise de Crédito")+SUMIFS('Kaio Dias'!$C$7:$C$374,'Kaio Dias'!$L$7:$L$374,"Análise de Crédito")+SUMIFS('Pablo Ruan'!$C$7:$C$382,'Pablo Ruan'!$L$7:$L$382,"Análise de Crédito")+SUMIFS(#REF!,#REF!,"Análise de Crédito") -> #REF! | D21: =IF(SUM($C$20:$C$26)=0,"",C21/SUM($C$20:$C$26)) -> #REF!
A22: Comitê | B22: =COUNTIFS('André Pullig'!$L$7:$L$396,"Comitê")+COUNTIFS('Betania Ribeiro'!$L$7:$L$400,"Comitê")+COUNTIFS('João Pullig'!$L$7:$L$385,"Comitê")+COUNTIFS('Kaio Dias'!$L$7:$L$374,"Comitê")+COUNTIFS('Pablo Ruan'!$L$7:$L$382,"Comitê")+COUNTIFS(#REF!,"Comitê") -> #REF! | C22: =SUMIFS('André Pullig'!$C$7:$C$396,'André Pullig'!$L$7:$L$396,"Comitê")+SUMIFS('Betania Ribeiro'!$C$7:$C$400,'Betania Ribeiro'!$L$7:$L$400,"Comitê")+SUMIFS('João Pullig'!$C$7:$C$385,'João Pullig'!$L$7:$L$385,"Comitê")+SUMIFS('Kaio Dias'!$C$7:$C$374,'Kaio Dias'!$L$7:$L$374,"Comitê")+SUMIFS('Pablo Ruan'!$C$7:$C$382,'Pablo Ruan'!$L$7:$L$382,"Comitê")+SUMIFS(#REF!,#REF!,"Comitê") -> #REF! | D22: =IF(SUM($C$20:$C$26)=0,"",C22/SUM($C$20:$C$26)) -> #REF!
A23: Aprovação | B23: =COUNTIFS('André Pullig'!$L$7:$L$396,"Aprovação")+COUNTIFS('Betania Ribeiro'!$L$7:$L$400,"Aprovação")+COUNTIFS('João Pullig'!$L$7:$L$385,"Aprovação")+COUNTIFS('Kaio Dias'!$L$7:$L$374,"Aprovação")+COUNTIFS('Pablo Ruan'!$L$7:$L$382,"Aprovação")+COUNTIFS(#REF!,"Aprovação") -> #REF! | C23: =SUMIFS('André Pullig'!$C$7:$C$396,'André Pullig'!$L$7:$L$396,"Aprovação")+SUMIFS('Betania Ribeiro'!$C$7:$C$400,'Betania Ribeiro'!$L$7:$L$400,"Aprovação")+SUMIFS('João Pullig'!$C$7:$C$385,'João Pullig'!$L$7:$L$385,"Aprovação")+SUMIFS('Kaio Dias'!$C$7:$C$374,'Kaio Dias'!$L$7:$L$374,"Aprovação")+SUMIFS('Pablo Ruan'!$C$7:$C$382,'Pablo Ruan'!$L$7:$L$382,"Aprovação")+SUMIFS(#REF!,#REF!,"Aprovação") -> #REF! | D23: =IF(SUM($C$20:$C$26)=0,"",C23/SUM($C$20:$C$26)) -> #REF!
A24: Assinatura de Contrato | B24: =COUNTIFS('André Pullig'!$L$7:$L$396,"Assinatura de Contrato")+COUNTIFS('Betania Ribeiro'!$L$7:$L$400,"Assinatura de Contrato")+COUNTIFS('João Pullig'!$L$7:$L$385,"Assinatura de Contrato")+COUNTIFS('Kaio Dias'!$L$7:$L$374,"Assinatura de Contrato")+COUNTIFS('Pablo Ruan'!$L$7:$L$382,"Assinatura de Contrato")+COUNTIFS(#REF!,"Assinatura de Contrato") -> #REF! | C24: =SUMIFS('André Pullig'!$C$7:$C$396,'André Pullig'!$L$7:$L$396,"Assinatura de Contrato")+SUMIFS('Betania Ribeiro'!$C$7:$C$400,'Betania Ribeiro'!$L$7:$L$400,"Assinatura de Contrato")+SUMIFS('João Pullig'!$C$7:$C$385,'João Pullig'!$L$7:$L$385,"Assinatura de Contrato")+SUMIFS('Kaio Dias'!$C$7:$C$374,'Kaio Dias'!$L$7:$L$374,"Assinatura de Contrato")+SUMIFS('Pablo Ruan'!$C$7:$C$382,'Pablo Ruan'!$L$7:$L$382,"Assinatura de Contrato")+SUMIFS(#REF!,#REF!,"Assinatura de Contrato") -> #REF! | D24: =IF(SUM($C$20:$C$26)=0,"",C24/SUM($C$20:$C$26)) -> #REF!
A25: Aprovado | B25: =COUNTIFS('André Pullig'!$L$7:$L$396,"Aprovado")+COUNTIFS('Betania Ribeiro'!$L$7:$L$400,"Aprovado")+COUNTIFS('João Pullig'!$L$7:$L$385,"Aprovado")+COUNTIFS('Kaio Dias'!$L$7:$L$374,"Aprovado")+COUNTIFS('Pablo Ruan'!$L$7:$L$382,"Aprovado")+COUNTIFS(#REF!,"Aprovado") -> #REF! | C25: =SUMIFS('André Pullig'!$C$7:$C$396,'André Pullig'!$L$7:$L$396,"Aprovado")+SUMIFS('Betania Ribeiro'!$C$7:$C$400,'Betania Ribeiro'!$L$7:$L$400,"Aprovado")+SUMIFS('João Pullig'!$C$7:$C$385,'João Pullig'!$L$7:$L$385,"Aprovado")+SUMIFS('Kaio Dias'!$C$7:$C$374,'Kaio Dias'!$L$7:$L$374,"Aprovado")+SUMIFS('Pablo Ruan'!$C$7:$C$382,'Pablo Ruan'!$L$7:$L$382,"Aprovado")+SUMIFS(#REF!,#REF!,"Aprovado") -> #REF! | D25: =IF(SUM($C$20:$C$26)=0,"",C25/SUM($C$20:$C$26)) -> #REF!
A26: Reprovado | B26: =COUNTIFS('André Pullig'!$L$7:$L$396,"Reprovado")+COUNTIFS('Betania Ribeiro'!$L$7:$L$400,"Reprovado")+COUNTIFS('João Pullig'!$L$7:$L$385,"Reprovado")+COUNTIFS('Kaio Dias'!$L$7:$L$374,"Reprovado")+COUNTIFS('Pablo Ruan'!$L$7:$L$382,"Reprovado")+COUNTIFS(#REF!,"Reprovado") -> #REF! | C26: =SUMIFS('André Pullig'!$C$7:$C$396,'André Pullig'!$L$7:$L$396,"Reprovado")+SUMIFS('Betania Ribeiro'!$C$7:$C$400,'Betania Ribeiro'!$L$7:$L$400,"Reprovado")+SUMIFS('João Pullig'!$C$7:$C$385,'João Pullig'!$L$7:$L$385,"Reprovado")+SUMIFS('Kaio Dias'!$C$7:$C$374,'Kaio Dias'!$L$7:$L$374,"Reprovado")+SUMIFS('Pablo Ruan'!$C$7:$C$382,'Pablo Ruan'!$L$7:$L$382,"Reprovado")+SUMIFS(#REF!,#REF!,"Reprovado") -> #REF! | D26: =IF(SUM($C$20:$C$26)=0,"",C26/SUM($C$20:$C$26)) -> #REF!
A28: POR TIPO DE OPERAÇÃO
A29: Tipo de operação | B29: Operações | C29: Volume | D29: Receita aprovada
A30: Capital de Giro | B30: =COUNTIFS('André Pullig'!$B$7:$B$396,"Capital de Giro")+COUNTIFS('Betania Ribeiro'!$B$7:$B$400,"Capital de Giro")+COUNTIFS('João Pullig'!$B$7:$B$385,"Capital de Giro")+COUNTIFS('Kaio Dias'!$B$7:$B$374,"Capital de Giro")+COUNTIFS('Pablo Ruan'!$B$7:$B$382,"Capital de Giro")+COUNTIFS(#REF!,"Capital de Giro") -> #REF! | C30: =SUMIFS('André Pullig'!$C$7:$C$396,'André Pullig'!$B$7:$B$396,"Capital de Giro")+SUMIFS('Betania Ribeiro'!$C$7:$C$400,'Betania Ribeiro'!$B$7:$B$400,"Capital de Giro")+SUMIFS('João Pullig'!$C$7:$C$385,'João Pullig'!$B$7:$B$385,"Capital de Giro")+SUMIFS('Kaio Dias'!$C$7:$C$374,'Kaio Dias'!$B$7:$B$374,"Capital de Giro")+SUMIFS('Pablo Ruan'!$C$7:$C$382,'Pablo Ruan'!$B$7:$B$382,"Capital de Giro")+SUMIFS(#REF!,#REF!,"Capital de Giro") -> #REF! | D30: =SUMIFS('André Pullig'!$E$7:$E$396,'André Pullig'!$B$7:$B$396,"Capital de Giro",'André Pullig'!$L$7:$L$396,"Aprovado")+SUMIFS('Betania Ribeiro'!$E$7:$E$400,'Betania Ribeiro'!$B$7:$B$400,"Capital de Giro",'Betania Ribeiro'!$L$7:$L$400,"Aprovado")+SUMIFS('João Pullig'!$E$7:$E$385,'João Pullig'!$B$7:$B$385,"Capital de Giro",'João Pullig'!$L$7:$L$385,"Aprovado")+SUMIFS('Kaio Dias'!$E$7:$E$374,'Kaio Dias'!$B$7:$B$374,"Capital de Giro",'Kaio Dias'!$L$7:$L$374,"Aprovado")+SUMIFS('Pablo Ruan'!$E$7:$E$382,'Pablo Ruan'!$B$7:$B$382,"Capital de Giro",'Pablo Ruan'!$L$7:$L$382,"Aprovado")+SUMIFS(#REF!,#REF!,"Capital de Giro",#REF!,"Aprovado") -> #REF!
A31: Pró-soluto | B31: =COUNTIFS('André Pullig'!$B$7:$B$396,"Pró-soluto")+COUNTIFS('Betania Ribeiro'!$B$7:$B$400,"Pró-soluto")+COUNTIFS('João Pullig'!$B$7:$B$385,"Pró-soluto")+COUNTIFS('Kaio Dias'!$B$7:$B$374,"Pró-soluto")+COUNTIFS('Pablo Ruan'!$B$7:$B$382,"Pró-soluto")+COUNTIFS(#REF!,"Pró-soluto") -> #REF! | C31: =SUMIFS('André Pullig'!$C$7:$C$396,'André Pullig'!$B$7:$B$396,"Pró-soluto")+SUMIFS('Betania Ribeiro'!$C$7:$C$400,'Betania Ribeiro'!$B$7:$B$400,"Pró-soluto")+SUMIFS('João Pullig'!$C$7:$C$385,'João Pullig'!$B$7:$B$385,"Pró-soluto")+SUMIFS('Kaio Dias'!$C$7:$C$374,'Kaio Dias'!$B$7:$B$374,"Pró-soluto")+SUMIFS('Pablo Ruan'!$C$7:$C$382,'Pablo Ruan'!$B$7:$B$382,"Pró-soluto")+SUMIFS(#REF!,#REF!,"Pró-soluto") -> #REF! | D31: =SUMIFS('André Pullig'!$E$7:$E$396,'André Pullig'!$B$7:$B$396,"Pró-soluto",'André Pullig'!$L$7:$L$396,"Aprovado")+SUMIFS('Betania Ribeiro'!$E$7:$E$400,'Betania Ribeiro'!$B$7:$B$400,"Pró-soluto",'Betania Ribeiro'!$L$7:$L$400,"Aprovado")+SUMIFS('João Pullig'!$E$7:$E$385,'João Pullig'!$B$7:$B$385,"Pró-soluto",'João Pullig'!$L$7:$L$385,"Aprovado")+SUMIFS('Kaio Dias'!$E$7:$E$374,'Kaio Dias'!$B$7:$B$374,"Pró-soluto",'Kaio Dias'!$L$7:$L$374,"Aprovado")+SUMIFS('Pablo Ruan'!$E$7:$E$382,'Pablo Ruan'!$B$7:$B$382,"Pró-soluto",'Pablo Ruan'!$L$7:$L$382,"Aprovado")+SUMIFS(#REF!,#REF!,"Pró-soluto",#REF!,"Aprovado") -> #REF!
A32: Antecipação de Recebíveis | B32: =COUNTIFS('André Pullig'!$B$7:$B$396,"Antecipação de Recebíveis")+COUNTIFS('Betania Ribeiro'!$B$7:$B$400,"Antecipação de Recebíveis")+COUNTIFS('João Pullig'!$B$7:$B$385,"Antecipação de Recebíveis")+COUNTIFS('Kaio Dias'!$B$7:$B$374,"Antecipação de Recebíveis")+COUNTIFS('Pablo Ruan'!$B$7:$B$382,"Antecipação de Recebíveis")+COUNTIFS(#REF!,"Antecipação de Recebíveis") -> #REF! | C32: =SUMIFS('André Pullig'!$C$7:$C$396,'André Pullig'!$B$7:$B$396,"Antecipação de Recebíveis")+SUMIFS('Betania Ribeiro'!$C$7:$C$400,'Betania Ribeiro'!$B$7:$B$400,"Antecipação de Recebíveis")+SUMIFS('João Pullig'!$C$7:$C$385,'João Pullig'!$B$7:$B$385,"Antecipação de Recebíveis")+SUMIFS('Kaio Dias'!$C$7:$C$374,'Kaio Dias'!$B$7:$B$374,"Antecipação de Recebíveis")+SUMIFS('Pablo Ruan'!$C$7:$C$382,'Pablo Ruan'!$B$7:$B$382,"Antecipação de Recebíveis")+SUMIFS(#REF!,#REF!,"Antecipação de Recebíveis") -> #REF! | D32: =SUMIFS('André Pullig'!$E$7:$E$396,'André Pullig'!$B$7:$B$396,"Antecipação de Recebíveis",'André Pullig'!$L$7:$L$396,"Aprovado")+SUMIFS('Betania Ribeiro'!$E$7:$E$400,'Betania Ribeiro'!$B$7:$B$400,"Antecipação de Recebíveis",'Betania Ribeiro'!$L$7:$L$400,"Aprovado")+SUMIFS('João Pullig'!$E$7:$E$385,'João Pullig'!$B$7:$B$385,"Antecipação de Recebíveis",'João Pullig'!$L$7:$L$385,"Aprovado")+SUMIFS('Kaio Dias'!$E$7:$E$374,'Kaio Dias'!$B$7:$B$374,"Antecipação de Recebíveis",'Kaio Dias'!$L$7:$L$374,"Aprovado")+SUMIFS('Pablo Ruan'!$E$7:$E$382,'Pablo Ruan'!$B$7:$B$382,"Antecipação de Recebíveis",'Pablo Ruan'!$L$7:$L$382,"Aprovado")+SUMIFS(#REF!,#REF!,"Antecipação de Recebíveis",#REF!,"Aprovado") -> #REF!
A33: Crédito Rural | B33: =COUNTIFS('André Pullig'!$B$7:$B$396,"Crédito Rural")+COUNTIFS('Betania Ribeiro'!$B$7:$B$400,"Crédito Rural")+COUNTIFS('João Pullig'!$B$7:$B$385,"Crédito Rural")+COUNTIFS('Kaio Dias'!$B$7:$B$374,"Crédito Rural")+COUNTIFS('Pablo Ruan'!$B$7:$B$382,"Crédito Rural")+COUNTIFS(#REF!,"Crédito Rural") -> #REF! | C33: =SUMIFS('André Pullig'!$C$7:$C$396,'André Pullig'!$B$7:$B$396,"Crédito Rural")+SUMIFS('Betania Ribeiro'!$C$7:$C$400,'Betania Ribeiro'!$B$7:$B$400,"Crédito Rural")+SUMIFS('João Pullig'!$C$7:$C$385,'João Pullig'!$B$7:$B$385,"Crédito Rural")+SUMIFS('Kaio Dias'!$C$7:$C$374,'Kaio Dias'!$B$7:$B$374,"Crédito Rural")+SUMIFS('Pablo Ruan'!$C$7:$C$382,'Pablo Ruan'!$B$7:$B$382,"Crédito Rural")+SUMIFS(#REF!,#REF!,"Crédito Rural") -> #REF! | D33: =SUMIFS('André Pullig'!$E$7:$E$396,'André Pullig'!$B$7:$B$396,"Crédito Rural",'André Pullig'!$L$7:$L$396,"Aprovado")+SUMIFS('Betania Ribeiro'!$E$7:$E$400,'Betania Ribeiro'!$B$7:$B$400,"Crédito Rural",'Betania Ribeiro'!$L$7:$L$400,"Aprovado")+SUMIFS('João Pullig'!$E$7:$E$385,'João Pullig'!$B$7:$B$385,"Crédito Rural",'João Pullig'!$L$7:$L$385,"Aprovado")+SUMIFS('Kaio Dias'!$E$7:$E$374,'Kaio Dias'!$B$7:$B$374,"Crédito Rural",'Kaio Dias'!$L$7:$L$374,"Aprovado")+SUMIFS('Pablo Ruan'!$E$7:$E$382,'Pablo Ruan'!$B$7:$B$382,"Crédito Rural",'Pablo Ruan'!$L$7:$L$382,"Aprovado")+SUMIFS(#REF!,#REF!,"Crédito Rural",#REF!,"Aprovado") -> #REF!
A34: Consórcio | B34: =COUNTIFS('André Pullig'!$B$7:$B$396,"Consórcio")+COUNTIFS('Betania Ribeiro'!$B$7:$B$400,"Consórcio")+COUNTIFS('João Pullig'!$B$7:$B$385,"Consórcio")+COUNTIFS('Kaio Dias'!$B$7:$B$374,"Consórcio")+COUNTIFS('Pablo Ruan'!$B$7:$B$382,"Consórcio")+COUNTIFS(#REF!,"Consórcio") -> #REF! | C34: =SUMIFS('André Pullig'!$C$7:$C$396,'André Pullig'!$B$7:$B$396,"Consórcio")+SUMIFS('Betania Ribeiro'!$C$7:$C$400,'Betania Ribeiro'!$B$7:$B$400,"Consórcio")+SUMIFS('João Pullig'!$C$7:$C$385,'João Pullig'!$B$7:$B$385,"Consórcio")+SUMIFS('Kaio Dias'!$C$7:$C$374,'Kaio Dias'!$B$7:$B$374,"Consórcio")+SUMIFS('Pablo Ruan'!$C$7:$C$382,'Pablo Ruan'!$B$7:$B$382,"Consórcio")+SUMIFS(#REF!,#REF!,"Consórcio") -> #REF! | D34: =SUMIFS('André Pullig'!$E$7:$E$396,'André Pullig'!$B$7:$B$396,"Consórcio",'André Pullig'!$L$7:$L$396,"Aprovado")+SUMIFS('Betania Ribeiro'!$E$7:$E$400,'Betania Ribeiro'!$B$7:$B$400,"Consórcio",'Betania Ribeiro'!$L$7:$L$400,"Aprovado")+SUMIFS('João Pullig'!$E$7:$E$385,'João Pullig'!$B$7:$B$385,"Consórcio",'João Pullig'!$L$7:$L$385,"Aprovado")+SUMIFS('Kaio Dias'!$E$7:$E$374,'Kaio Dias'!$B$7:$B$374,"Consórcio",'Kaio Dias'!$L$7:$L$374,"Aprovado")+SUMIFS('Pablo Ruan'!$E$7:$E$382,'Pablo Ruan'!$B$7:$B$382,"Consórcio",'Pablo Ruan'!$L$7:$L$382,"Aprovado")+SUMIFS(#REF!,#REF!,"Consórcio",#REF!,"Aprovado") -> #REF!
A35: Venda de Ativos | B35: =COUNTIFS('André Pullig'!$B$7:$B$396,"Venda de Ativos")+COUNTIFS('Betania Ribeiro'!$B$7:$B$400,"Venda de Ativos")+COUNTIFS('João Pullig'!$B$7:$B$385,"Venda de Ativos")+COUNTIFS('Kaio Dias'!$B$7:$B$374,"Venda de Ativos")+COUNTIFS('Pablo Ruan'!$B$7:$B$382,"Venda de Ativos")+COUNTIFS(#REF!,"Venda de Ativos") -> #REF! | C35: =SUMIFS('André Pullig'!$C$7:$C$396,'André Pullig'!$B$7:$B$396,"Venda de Ativos")+SUMIFS('Betania Ribeiro'!$C$7:$C$400,'Betania Ribeiro'!$B$7:$B$400,"Venda de Ativos")+SUMIFS('João Pullig'!$C$7:$C$385,'João Pullig'!$B$7:$B$385,"Venda de Ativos")+SUMIFS('Kaio Dias'!$C$7:$C$374,'Kaio Dias'!$B$7:$B$374,"Venda de Ativos")+SUMIFS('Pablo Ruan'!$C$7:$C$382,'Pablo Ruan'!$B$7:$B$382,"Venda de Ativos")+SUMIFS(#REF!,#REF!,"Venda de Ativos") -> #REF! | D35: =SUMIFS('André Pullig'!$E$7:$E$396,'André Pullig'!$B$7:$B$396,"Venda de Ativos",'André Pullig'!$L$7:$L$396,"Aprovado")+SUMIFS('Betania Ribeiro'!$E$7:$E$400,'Betania Ribeiro'!$B$7:$B$400,"Venda de Ativos",'Betania Ribeiro'!$L$7:$L$400,"Aprovado")+SUMIFS('João Pullig'!$E$7:$E$385,'João Pullig'!$B$7:$B$385,"Venda de Ativos",'João Pullig'!$L$7:$L$385,"Aprovado")+SUMIFS('Kaio Dias'!$E$7:$E$374,'Kaio Dias'!$B$7:$B$374,"Venda de Ativos",'Kaio Dias'!$L$7:$L$374,"Aprovado")+SUMIFS('Pablo Ruan'!$E$7:$E$382,'Pablo Ruan'!$B$7:$B$382,"Venda de Ativos",'Pablo Ruan'!$L$7:$L$382,"Aprovado")+SUMIFS(#REF!,#REF!,"Venda de Ativos",#REF!,"Aprovado") -> #REF!
A36: FGI | B36: =COUNTIFS('André Pullig'!$B$7:$B$396,"FGI")+COUNTIFS('Betania Ribeiro'!$B$7:$B$400,"FGI")+COUNTIFS('João Pullig'!$B$7:$B$385,"FGI")+COUNTIFS('Kaio Dias'!$B$7:$B$374,"FGI")+COUNTIFS('Pablo Ruan'!$B$7:$B$382,"FGI")+COUNTIFS(#REF!,"FGI") -> #REF! | C36: =SUMIFS('André Pullig'!$C$7:$C$396,'André Pullig'!$B$7:$B$396,"FGI")+SUMIFS('Betania Ribeiro'!$C$7:$C$400,'Betania Ribeiro'!$B$7:$B$400,"FGI")+SUMIFS('João Pullig'!$C$7:$C$385,'João Pullig'!$B$7:$B$385,"FGI")+SUMIFS('Kaio Dias'!$C$7:$C$374,'Kaio Dias'!$B$7:$B$374,"FGI")+SUMIFS('Pablo Ruan'!$C$7:$C$382,'Pablo Ruan'!$B$7:$B$382,"FGI")+SUMIFS(#REF!,#REF!,"FGI") -> #REF! | D36: =SUMIFS('André Pullig'!$E$7:$E$396,'André Pullig'!$B$7:$B$396,"FGI",'André Pullig'!$L$7:$L$396,"Aprovado")+SUMIFS('Betania Ribeiro'!$E$7:$E$400,'Betania Ribeiro'!$B$7:$B$400,"FGI",'Betania Ribeiro'!$L$7:$L$400,"Aprovado")+SUMIFS('João Pullig'!$E$7:$E$385,'João Pullig'!$B$7:$B$385,"FGI",'João Pullig'!$L$7:$L$385,"Aprovado")+SUMIFS('Kaio Dias'!$E$7:$E$374,'Kaio Dias'!$B$7:$B$374,"FGI",'Kaio Dias'!$L$7:$L$374,"Aprovado")+SUMIFS('Pablo Ruan'!$E$7:$E$382,'Pablo Ruan'!$B$7:$B$382,"FGI",'Pablo Ruan'!$L$7:$L$382,"Aprovado")+SUMIFS(#REF!,#REF!,"FGI",#REF!,"Aprovado") -> #REF!
A37: Serviço Cadastral | B37: =COUNTIFS('André Pullig'!$B$7:$B$396,"Serviço Cadastral")+COUNTIFS('Betania Ribeiro'!$B$7:$B$400,"Serviço Cadastral")+COUNTIFS('João Pullig'!$B$7:$B$385,"Serviço Cadastral")+COUNTIFS('Kaio Dias'!$B$7:$B$374,"Serviço Cadastral")+COUNTIFS('Pablo Ruan'!$B$7:$B$382,"Serviço Cadastral")+COUNTIFS(#REF!,"Serviço Cadastral") -> #REF! | C37: =SUMIFS('André Pullig'!$C$7:$C$396,'André Pullig'!$B$7:$B$396,"Serviço Cadastral")+SUMIFS('Betania Ribeiro'!$C$7:$C$400,'Betania Ribeiro'!$B$7:$B$400,"Serviço Cadastral")+SUMIFS('João Pullig'!$C$7:$C$385,'João Pullig'!$B$7:$B$385,"Serviço Cadastral")+SUMIFS('Kaio Dias'!$C$7:$C$374,'Kaio Dias'!$B$7:$B$374,"Serviço Cadastral")+SUMIFS('Pablo Ruan'!$C$7:$C$382,'Pablo Ruan'!$B$7:$B$382,"Serviço Cadastral")+SUMIFS(#REF!,#REF!,"Serviço Cadastral") -> #REF! | D37: =SUMIFS('André Pullig'!$E$7:$E$396,'André Pullig'!$B$7:$B$396,"Serviço Cadastral",'André Pullig'!$L$7:$L$396,"Aprovado")+SUMIFS('Betania Ribeiro'!$E$7:$E$400,'Betania Ribeiro'!$B$7:$B$400,"Serviço Cadastral",'Betania Ribeiro'!$L$7:$L$400,"Aprovado")+SUMIFS('João Pullig'!$E$7:$E$385,'João Pullig'!$B$7:$B$385,"Serviço Cadastral",'João Pullig'!$L$7:$L$385,"Aprovado")+SUMIFS('Kaio Dias'!$E$7:$E$374,'Kaio Dias'!$B$7:$B$374,"Serviço Cadastral",'Kaio Dias'!$L$7:$L$374,"Aprovado")+SUMIFS('Pablo Ruan'!$E$7:$E$382,'Pablo Ruan'!$B$7:$B$382,"Serviço Cadastral",'Pablo Ruan'!$L$7:$L$382,"Aprovado")+SUMIFS(#REF!,#REF!,"Serviço Cadastral",#REF!,"Aprovado") -> #REF!
A38: Venda de Colégio | B38: =COUNTIFS('André Pullig'!$B$7:$B$396,"Venda de Colégio")+COUNTIFS('Betania Ribeiro'!$B$7:$B$400,"Venda de Colégio")+COUNTIFS('João Pullig'!$B$7:$B$385,"Venda de Colégio")+COUNTIFS('Kaio Dias'!$B$7:$B$374,"Venda de Colégio")+COUNTIFS('Pablo Ruan'!$B$7:$B$382,"Venda de Colégio")+COUNTIFS(#REF!,"Venda de Colégio") -> #REF! | C38: =SUMIFS('André Pullig'!$C$7:$C$396,'André Pullig'!$B$7:$B$396,"Venda de Colégio")+SUMIFS('Betania Ribeiro'!$C$7:$C$400,'Betania Ribeiro'!$B$7:$B$400,"Venda de Colégio")+SUMIFS('João Pullig'!$C$7:$C$385,'João Pullig'!$B$7:$B$385,"Venda de Colégio")+SUMIFS('Kaio Dias'!$C$7:$C$374,'Kaio Dias'!$B$7:$B$374,"Venda de Colégio")+SUMIFS('Pablo Ruan'!$C$7:$C$382,'Pablo Ruan'!$B$7:$B$382,"Venda de Colégio")+SUMIFS(#REF!,#REF!,"Venda de Colégio") -> #REF! | D38: =SUMIFS('André Pullig'!$E$7:$E$396,'André Pullig'!$B$7:$B$396,"Venda de Colégio",'André Pullig'!$L$7:$L$396,"Aprovado")+SUMIFS('Betania Ribeiro'!$E$7:$E$400,'Betania Ribeiro'!$B$7:$B$400,"Venda de Colégio",'Betania Ribeiro'!$L$7:$L$400,"Aprovado")+SUMIFS('João Pullig'!$E$7:$E$385,'João Pullig'!$B$7:$B$385,"Venda de Colégio",'João Pullig'!$L$7:$L$385,"Aprovado")+SUMIFS('Kaio Dias'!$E$7:$E$374,'Kaio Dias'!$B$7:$B$374,"Venda de Colégio",'Kaio Dias'!$L$7:$L$374,"Aprovado")+SUMIFS('Pablo Ruan'!$E$7:$E$382,'Pablo Ruan'!$B$7:$B$382,"Venda de Colégio",'Pablo Ruan'!$L$7:$L$382,"Aprovado")+SUMIFS(#REF!,#REF!,"Venda de Colégio",#REF!,"Aprovado") -> #REF!
A39: Conta / Maquininha | B39: =COUNTIFS('André Pullig'!$B$7:$B$396,"Conta / Maquininha")+COUNTIFS('Betania Ribeiro'!$B$7:$B$400,"Conta / Maquininha")+COUNTIFS('João Pullig'!$B$7:$B$385,"Conta / Maquininha")+COUNTIFS('Kaio Dias'!$B$7:$B$374,"Conta / Maquininha")+COUNTIFS('Pablo Ruan'!$B$7:$B$382,"Conta / Maquininha")+COUNTIFS(#REF!,"Conta / Maquininha") -> #REF! | C39: =SUMIFS('André Pullig'!$C$7:$C$396,'André Pullig'!$B$7:$B$396,"Conta / Maquininha")+SUMIFS('Betania Ribeiro'!$C$7:$C$400,'Betania Ribeiro'!$B$7:$B$400,"Conta / Maquininha")+SUMIFS('João Pullig'!$C$7:$C$385,'João Pullig'!$B$7:$B$385,"Conta / Maquininha")+SUMIFS('Kaio Dias'!$C$7:$C$374,'Kaio Dias'!$B$7:$B$374,"Conta / Maquininha")+SUMIFS('Pablo Ruan'!$C$7:$C$382,'Pablo Ruan'!$B$7:$B$382,"Conta / Maquininha")+SUMIFS(#REF!,#REF!,"Conta / Maquininha") -> #REF! | D39: =SUMIFS('André Pullig'!$E$7:$E$396,'André Pullig'!$B$7:$B$396,"Conta / Maquininha",'André Pullig'!$L$7:$L$396,"Aprovado")+SUMIFS('Betania Ribeiro'!$E$7:$E$400,'Betania Ribeiro'!$B$7:$B$400,"Conta / Maquininha",'Betania Ribeiro'!$L$7:$L$400,"Aprovado")+SUMIFS('João Pullig'!$E$7:$E$385,'João Pullig'!$B$7:$B$385,"Conta / Maquininha",'João Pullig'!$L$7:$L$385,"Aprovado")+SUMIFS('Kaio Dias'!$E$7:$E$374,'Kaio Dias'!$B$7:$B$374,"Conta / Maquininha",'Kaio Dias'!$L$7:$L$374,"Aprovado")+SUMIFS('Pablo Ruan'!$E$7:$E$382,'Pablo Ruan'!$B$7:$B$382,"Conta / Maquininha",'Pablo Ruan'!$L$7:$L$382,"Aprovado")+SUMIFS(#REF!,#REF!,"Conta / Maquininha",#REF!,"Aprovado") -> #REF!
A40: Câmbio | B40: =COUNTIFS('André Pullig'!$B$7:$B$396,"Câmbio")+COUNTIFS('Betania Ribeiro'!$B$7:$B$400,"Câmbio")+COUNTIFS('João Pullig'!$B$7:$B$385,"Câmbio")+COUNTIFS('Kaio Dias'!$B$7:$B$374,"Câmbio")+COUNTIFS('Pablo Ruan'!$B$7:$B$382,"Câmbio")+COUNTIFS(#REF!,"Câmbio") -> #REF! | C40: =SUMIFS('André Pullig'!$C$7:$C$396,'André Pullig'!$B$7:$B$396,"Câmbio")+SUMIFS('Betania Ribeiro'!$C$7:$C$400,'Betania Ribeiro'!$B$7:$B$400,"Câmbio")+SUMIFS('João Pullig'!$C$7:$C$385,'João Pullig'!$B$7:$B$385,"Câmbio")+SUMIFS('Kaio Dias'!$C$7:$C$374,'Kaio Dias'!$B$7:$B$374,"Câmbio")+SUMIFS('Pablo Ruan'!$C$7:$C$382,'Pablo Ruan'!$B$7:$B$382,"Câmbio")+SUMIFS(#REF!,#REF!,"Câmbio") -> #REF! | D40: =SUMIFS('André Pullig'!$E$7:$E$396,'André Pullig'!$B$7:$B$396,"Câmbio",'André Pullig'!$L$7:$L$396,"Aprovado")+SUMIFS('Betania Ribeiro'!$E$7:$E$400,'Betania Ribeiro'!$B$7:$B$400,"Câmbio",'Betania Ribeiro'!$L$7:$L$400,"Aprovado")+SUMIFS('João Pullig'!$E$7:$E$385,'João Pullig'!$B$7:$B$385,"Câmbio",'João Pullig'!$L$7:$L$385,"Aprovado")+SUMIFS('Kaio Dias'!$E$7:$E$374,'Kaio Dias'!$B$7:$B$374,"Câmbio",'Kaio Dias'!$L$7:$L$374,"Aprovado")+SUMIFS('Pablo Ruan'!$E$7:$E$382,'Pablo Ruan'!$B$7:$B$382,"Câmbio",'Pablo Ruan'!$L$7:$L$382,"Aprovado")+SUMIFS(#REF!,#REF!,"Câmbio",#REF!,"Aprovado") -> #REF!
